Workbook

Sheet 同時_h=m
B1: 1. Hàm lượng xi măng (T):
B2: § 同時改良：T1 = | F2: T/m3
B3: § 二次改良：T2 = | F3: T/m3 | J3: 同時改良 | K3: m2/1T | O3: 区 分 | Q3: TNF工法[同時改良]
K4: =1/E2/E6 -> #DIV/0! | L4: 1.21 | M4: =K4/L4 -> #DIV/0! | O4: 長期許容支持力度 | Q4: Lfe = | R4: 80 | S4: kN/m2
B5: 2. Chiều dày lớp cải tạo (h): | L5: 33.45 | M5: =L5/K4 -> #DIV/0! | O5: 使用固化材 | Q5: ジオセット | R5: 200
B6: § 同時改良：h1 = | F6: m | K6: m2/2T | O6: 添加量 | Q6: 同時改良部 | R6: =E2*1000 -> 0 | S6: kg/m3 | T6: Revit
B7: § 二次改良：h2 = | F7: m | K7: =2/E2/E6 -> #DIV/0! | L7: =L4 -> 1.21 | M7: =K7/L7 -> #DIV/0! | O7: 改良厚 | Q7: H = | R7: =E6*1000 -> 0 | S7: mm | T7: 1T
B8: § 外構：h3 = | F8: m | L8: =L5 -> 33.45 | M8: =M5 -> #DIV/0! | Q8: 改良天端 GL | R8: =E10-R23 -> 0 | S8: mm | T8: 2T
K9: m2/3T | Q9: 改良下端 GL | R9: =E10-R23-R7 -> 0 | S9: mm | T9: 3T
B10: 3. Cao trình cải tạo | F10: mm | K10: =3/E2/E6 -> #DIV/0! | L10: =L4 -> 1.21 | M10: =K10/L10 -> #DIV/0! | O10: 改良面積 | Q10: 同時改良部： | R10: =ROUNDUP(F32,0) -> 0 | S10: m2 | T10: 4T
L11: =L5 -> 33.45 | M11: =M5 -> #DIV/0! | O11: 改良土量 | Q11: 同時改良部： | R11: =ROUNDUP(F35,0) -> 0 | S11: m3 | T11: 5T
B12: 4. Diện tích các lớp cải tạo (S): | K12: m2/4T | O12: 固化材使用数量 | Q12: 同時改良部： | S12: t
B13: § Tổng diện tích đất cải tạo đồng thời | K13: =4/E2/E6 -> #DIV/0! | L13: =L4 -> 1.21 | M13: =K13/L13 -> #DIV/0! | Q13: ※ 区画割付内特記無きは 2t とする | T13: SUM | U13: =SUM(LEFT(T7,1)*U7,LEFT(T8,1)*U8,LEFT(T9,1)*U9,LEFT(T10,1)*U10,LEFT(T11,1)*U11) -> 0
B14: STT | C14: SL | D14: D | E14: R | F14: D×R | L14: =L5 -> 33.45 | M14: =M5 -> #DIV/0! | Q14: ※ ○内数値は固化材数量(t)を示す | T14: +- | U14: =+I38-U13 -> 0
B15: 1 | C15: 1 | D15: 1 | F15: =IF(C15="","",C15*D15*E15) -> 0 | Q15: ※ 供試体採取箇所: 1箇所
B16: 2 | C16: 1 | D16: -1 | E16: =F30 -> 0 | F16: =IF(C16="","",C16*D16*E16) -> 0
F17: =SUM(F15:F16) -> 0
B19: § Tổng diện tích si-ma | J19: 二次改良 | K19: m2/1T | O19: 区 分 | Q19: TNF工法[二次改良]
B20: STT | C20: SL | D20: D | E20: R | F20: D×R | G20: KL/1ô | H20: Round | K20: =1/E3/E7 -> #DIV/0! | L20: 5.51 | M20: =K20/L20 -> #DIV/0! | O20: 長期許容支持力度 | Q20: Lfe = | R20: =R4 -> 80 | S20: kN/m2
B21: 1 | D21: 1 | F21: =IF(C21="","",C21*D21*E21) | G21: =IF(C21="","",E21/(1/$E$3/$E$7)) | H21: =IF(C21="","",ROUNDUP(G21,0)) | L21: 9.639 | M21: =L21/K20 -> #DIV/0! | O21: 使用固化材 | Q21: ジオセット | R21: =R5 -> 200
B22: 2 | D22: 1 | F22: =IF(C22="","",C22*D22*E22) | G22: =IF(C22="","",E22/(1/$E$3/$E$7)) | H22: =IF(C22="","",ROUNDUP(G22,0)) | K22: m2/2T | O22: 添加量 | Q22: 二次改良部 | R22: =E3*1000 -> 0 | S22: kg/m3 | T22: Revit
B23: 3 | D23: 1 | F23: =IF(C23="","",C23*D23*E23) | G23: =IF(C23="","",E23/(1/$E$3/$E$7)) | H23: =IF(C23="","",ROUNDUP(G23,0)) | K23: =2/E3/E7 -> #DIV/0! | L23: =L20 -> 5.51 | M23: =K23/L23 -> #DIV/0! | O23: 改良厚 | Q23: H = | R23: =E7*1000 -> 0 | S23: mm | T23: 1T
B24: 4 | D24: 1 | F24: =IF(C24="","",C24*D24*E24) | G24: =IF(C24="","",E24/(1/$E$3/$E$7)) | H24: =IF(C24="","",ROUNDUP(G24,0)) | L24: =L21 -> 9.639 | M24: =M21 -> #DIV/0! | Q24: 改良天端 GL | R24: =E10 -> 0 | S24: mm | T24: 2T
B25: 5 | D25: 1 | F25: =IF(C25="","",C25*D25*E25) | G25: =IF(C25="","",E25/(1/$E$3/$E$7)) | H25: =IF(C25="","",ROUNDUP(G25,0)) | K25: m2/3T | Q25: 改良下端 GL | R25: =E10-R23 -> 0 | S25: mm | T25: 3T
B26: 6 | D26: 1 | F26: =IF(C26="","",C26*D26*E26) | G26: =IF(C26="","",E26/(1/$E$3/$E$7)) | H26: =IF(C26="","",ROUNDUP(G26,0)) | K26: =3/E3/E7 -> #DIV/0! | L26: =L20 -> 5.51 | M26: =K26/L26 -> #DIV/0! | O26: 改良面積 | Q26: 二次改良部： | R26: =ROUNDUP(F33,0) -> 0 | S26: m2 | T26: 4T
B27: 7 | D27: 1 | F27: =IF(C27="","",C27*D27*E27) | G27: =IF(C27="","",E27/(1/$E$3/$E$7)) | H27: =IF(C27="","",ROUNDUP(G27,0)) | L27: =L21 -> 9.639 | M27: =M21 -> #DIV/0! | O27: 改良土量 | Q27: 二次改良部： | R27: =ROUNDUP(F36,0) -> 0 | S27: m3 | T27: 5T
B28: 8 | D28: 1 | F28: =IF(C28="","",C28*D28*E28) | G28: =IF(C28="","",E28/(1/$E$3/$E$7)) | H28: =IF(C28="","",ROUNDUP(G28,0)) | K28: m2/4T | O28: 固化材使用数量 | Q28: 二次改良部： | S28: t
B29: 9 | D29: 1 | F29: =IF(C29="","",C29*D29*E29) | G29: =IF(C29="","",E29/(1/$E$3/$E$7)) | H29: =IF(C29="","",ROUNDUP(G29,0)) | K29: =4/E3/E7 -> #DIV/0! | L29: =L20 -> 5.51 | M29: =K29/L29 -> #DIV/0! | Q29: ※ 区画割付内特記無きは 1t とする | T29: SUM | U29: =SUM(LEFT(T23,1)*U23,LEFT(T24,1)*U24,LEFT(T25,1)*U25,LEFT(T26,1)*U26,LEFT(T27,1)*U27) -> 0
F30: =SUM(F21:F29) -> 0 | G30: Sum all | H30: =SUMPRODUCT(C21:C29,H21:H29) -> 0 | L30: =L21 -> 9.639 | M30: =M21 -> #DIV/0! | Q30: ※ ○内数値は固化材数量(t)を示す | T30: +- | U30: =I39-U29 -> 0
Q31: ※ 供試体採取箇所: 1箇所
B32: § 同時改良：S1 = | F32: =SUM(F17) -> 0 | G32: (m2)
B33: § 二次改良：S2 = | F33: =F30 -> 0 | G33: (m2)
B34: 5. Thể tích các lớp cải tạo (V = S×h):
B35: § 同時改良：Ⅴ1 = | F35: =PRODUCT(F32,E6) -> 0 | G35: (m3)
B36: § 二次改良：Ⅴ2 = | F36: =PRODUCT(F33,E7) -> 0 | G36: (m3) | J36: 外構 | K36: m2/1T | O36: 区 分 | Q36: TNF工法[外構]
B37: 6. Khối lượng xi măng cần thiết (N = V×T): | K37: =1/E3/E8 -> #DIV/0! | L37: 5.51 | M37: =K37/L37 -> #DIV/0! | O37: 長期許容支持力度 | Q37: Lfe = | R37: =R21 -> 200 | S37: kN/m2
B38: § 同時改良：N1 = | F38: =PRODUCT(F35,E2) -> 0 | G38: (T) | H38: +2% | I38: =ROUNDUP(F38+F38*2%,0) -> 0 | L38: 9.639 | M38: =L38/K37 -> #DIV/0! | O38: 使用固化材 | Q38: ジオセット | R38: =R22 -> 0
B39: § 二次改良：N2 = | F39: =PRODUCT(F36,E3) -> 0 | G39: (T) | H39: +2% | I39: =ROUNDUP(F39+F39*2%,0) -> 0 | K39: m2/2T | O39: 添加量 | R39: *** | S39: kg/m3 | T39: Revit
K40: =2/E3/E8 -> #DIV/0! | L40: =L37 -> 5.51 | M40: =K40/L40 -> #DIV/0! | O40: 改良厚 | R40: *** | S40: mm | T40: 1T
B41: 7. Diện tích Gaikou cải tạo (S): | L41: =L38 -> 9.639 | M41: =M38 -> #DIV/0! | Q41: 改良天端 GL | R41: *** | S41: mm | T41: 2T
...

Sheet 一次二次_h=m
B1: 1. Hàm lượng xi măng (T):
B2: § 一次改良：T1 = | F2: T/m3
B3: § 二次改良：T2 = | F3: T/m3 | G3: axb=A | J3: 一次改良 | K3: m2/1T | O3: 区 分 | Q3: TNF工法[一次改良]
G4: 20 | H4: =H5*K4 -> #DIV/0! | I4: 5 | K4: =1/E2/E6 -> #DIV/0! | L4: 3.14 | M4: =K4/L4 -> #DIV/0! | O4: 長期許容支持力度 | Q4: Lfe = | R4: 80 | S4: kN/m2
B5: 2. Chiều dày lớp cải tạo (h): | G5: =IF(G4>H4, ROUNDUP(((G4-H4)/I4)*1000, -1), ROUNDDOWN(ABS((G4-H4)/I4)*1000, -1)) -> #DIV/0! | H5: 4 | I5: =H4/I4 -> #DIV/0! | L5: 103.456 | M5: =L5/K4 -> #DIV/0! | O5: 使用固化材 | Q5: ジオセット | R5: 200
B6: § 一次改良：h1 = | F6: m | K6: m2/2T | O6: 添加量 | Q6: 一次改良部 | R6: =E2*1000 -> 0 | S6: kg/m3 | T6: Revit
B7: § 二次改良：h2 = | F7: m | K7: =2/E2/E6 -> #DIV/0! | L7: =L4 -> 3.14 | M7: =K7/L7 -> #DIV/0! | O7: 改良厚 | Q7: H = | R7: =E6*1000 -> 0 | S7: mm | T7: 1T
B8: § 外構：h3 = | F8: m | L8: =L5 -> 103.456 | M8: =M5 -> #DIV/0! | Q8: 改良天端 GL | R8: =E10-R23 -> 0 | S8: mm | T8: 2T
K9: m2/3T | Q9: 改良下端 GL | R9: =E10-R23-R7 -> 0 | S9: mm | T9: 3T
B10: 3. Cao trình cải tạo | F10: mm | K10: =3/E2/E6 -> #DIV/0! | L10: =L4 -> 3.14 | M10: =K10/L10 -> #DIV/0! | O10: 改良面積 | Q10: 一次改良部： | R10: =ROUNDUP(F25,0) -> 0 | S10: m2 | T10: 4T
L11: =L5 -> 103.456 | M11: =M5 -> #DIV/0! | O11: 改良土量 | Q11: 一次改良部： | R11: =ROUNDUP(F28,0) -> 0 | S11: m3 | T11: 5T
B12: 4. Diện tích các lớp cải tạo (S): | K12: m2/4T | O12: 固化材使用数量 | Q12: 一次改良部： | S12: t
B13: § Tổng diện tích đất cải tạo lớp 1 | K13: =4/E2/E6 -> #DIV/0! | L13: =L4 -> 3.14 | M13: =K13/L13 -> #DIV/0! | Q13: ※ 区画割付内特記無きは 2t とする | T13: SUM | U13: =SUM(LEFT(T7,1)*U7,LEFT(T8,1)*U8,LEFT(T9,1)*U9,LEFT(T10,1)*U10,LEFT(T11,1)*U11) -> 0
B14: STT | C14: SL | D14: D | E14: R | F14: D×R | L14: =L5 -> 103.456 | M14: =M5 -> #DIV/0! | Q14: ※ ○内数値は固化材数量(t)を示す | T14: +- | U14: =I31-U13 -> 0
B15: 1 | C15: 1 | D15: 1 | F15: =IF(C15="","",C15*D15*E15) -> 0 | Q15: ※ 供試体採取箇所: 1箇所
B16: 2 | D16: 1 | F16: =IF(C16="","",C16*D16*E16)
F17: =SUM(F15:F16) -> 0
B19: § Tổng diện tích đất cải tạo lớp 2 | G19: axb=A | J19: 二次改良 | K19: m2/1T | O19: 区 分 | Q19: TNF工法[二次改良]
B20: STT | C20: SL | D20: D | E20: R | F20: D×R | G20: 20 | H20: =H21*K20 -> #DIV/0! | I20: 5 | K20: =1/E3/E7 -> #DIV/0! | L20: 3 | M20: =K20/L20 -> #DIV/0! | O20: 長期許容支持力度 | Q20: Lfe = | R20: =R4 -> 80 | S20: kN/m2
B21: 1 | C21: 1 | D21: 1 | F21: =IF(C21="","",C21*D21*E21) -> 0 | G21: =IF(G20>H20, ROUNDUP(((G20-H20)/I20)*1000, -1), ROUNDDOWN(ABS((G20-H20)/I20)*1000, -1)) -> #DIV/0! | H21: 4 | I21: =H20/I20 -> #DIV/0! | L21: 58.235 | M21: =L21/K20 -> #DIV/0! | O21: 使用固化材 | Q21: ジオセット | R21: =R5 -> 200
B22: 2 | D22: 1 | F22: =IF(C22="","",C22*D22*E22) | K22: m2/2T | O22: 添加量 | Q22: 二次改良部 | R22: =E3*1000 -> 0 | S22: kg/m3 | T22: Revit
F23: =SUM(F21:F22) -> 0 | K23: =2/E3/E7 -> #DIV/0! | L23: =L20 -> 3 | M23: =K23/L23 -> #DIV/0! | O23: 改良厚 | Q23: H = | R23: =E7*1000 -> 0 | S23: mm | T23: 1T
L24: =L21 -> 58.235 | M24: =M21 -> #DIV/0! | Q24: 改良天端 GL | R24: =E10 -> 0 | S24: mm | T24: 2T
B25: § 一次改良：S1 = | F25: =F17 -> 0 | G25: (m2) | K25: m2/3T | Q25: 改良下端 GL | R25: =E10-R23 -> 0 | S25: mm | T25: 3T
B26: § 二次改良：S2 = | F26: =F23 -> 0 | G26: (m2) | K26: =3/E3/E7 -> #DIV/0! | L26: =L20 -> 3 | M26: =K26/L26 -> #DIV/0! | O26: 改良面積 | Q26: 二次改良部： | R26: =ROUNDUP(F26,0) -> 0 | S26: m2 | T26: 4T
B27: 5. Thể tích các lớp cải tạo (V = S×h): | L27: =L21 -> 58.235 | M27: =M21 -> #DIV/0! | O27: 改良土量 | Q27: 二次改良部： | R27: =ROUNDUP(F29,0) -> 0 | S27: m3 | T27: 5T
B28: § 一次改良：Ⅴ1 = | F28: =PRODUCT(F25,E6) -> 0 | G28: (m3) | K28: m2/4T | O28: 固化材使用数量 | Q28: 二次改良部： | S28: t
B29: § 二次改良：Ⅴ2 = | F29: =PRODUCT(F26,E7) -> 0 | G29: (m3) | K29: =4/E3/E7 -> #DIV/0! | L29: =L20 -> 3 | M29: =K29/L29 -> #DIV/0! | Q29: ※ 区画割付内特記無きは 1t とする | T29: SUM | U29: =SUM(LEFT(T23,1)*U23,LEFT(T24,1)*U24,LEFT(T25,1)*U25,LEFT(T26,1)*U26,LEFT(T27,1)*U27) -> 0
B30: 6. Khối lượng xi măng cần thiết (N = V×T): | L30: =L21 -> 58.235 | M30: =M21 -> #DIV/0! | Q30: ※ ○内数値は固化材数量(t)を示す | T30: +- | U30: =I32-U29 -> 0
B31: § 一次改良：N1 = | F31: =PRODUCT(F28,E2) -> 0 | G31: (T) | H31: +2% | I31: =ROUNDUP(F31+F31*2%,0) -> 0 | Q31: ※ 供試体採取箇所: 1箇所
B32: § 二次改良：N2 = | F32: =PRODUCT(F29,E3) -> 0 | G32: (T) | H32: +2% | I32: =ROUNDUP(F32+F32*2%,0) -> 0
B34: 7. Diện tích Gaikou cải tạo (S):
B35: § Tổng diện tích đất Gaiko cải tạo
B36: STT | C36: SL | D36: D | E36: R | F36: D×R | J36: 外構 | K36: m2/1T | O36: 区 分 | Q36: TNF工法[外構]
B37: 1 | C37: 1 | D37: 1 | E37: 322.037 | F37: =IF(C37="","",C37*D37*E37) -> 322.037 | K37: =1/E3/E8 -> #DIV/0! | L37: 4 | M37: =K37/L37 -> #DIV/0! | O37: 長期許容支持力度 | Q37: Lfe = | R37: =R21 -> 200 | S37: kN/m2
B38: 2 | F38: =IF(C38="","",C38*D38*E38) | L38: 26.951 | M38: =L38/K37 -> #DIV/0! | O38: 使用固化材 | Q38: ジオセット | R38: =R22 -> 0
F39: =SUM(F37:F38) -> 322.037 | K39: m2/2T | O39: 添加量 | R39: *** | S39: kg/m3 | T39: Revit
B40: § 外構: S3= | F40: =F39 -> 322.037 | G40: (m2) | K40: =2/E3/E8 -> #DIV/0! | L40: =L37 -> 4 | M40: =K40/L40 -> #DIV/0! | O40: 改良厚 | R40: *** | S40: mm | T40: 1T
B41: § 外構: V3= | F41: =PRODUCT(F40,E8) -> 322.037 | G41: (m3) | L41: =L38 -> 26.951 | M41: =M38 -> #DIV/0! | Q41: 改良天端 GL | R41: *** | S41: mm | T41: 2T
B42: § 外構: N3= | F42: =F41*E3 -> 0 | G42: (T) | H42: +2% | I42: =ROUNDUP(F42+F42*2%,0) -> 0 | K42: m2/3T | Q42: 改良下端 GL | R42: *** | S42: mm | T42: 3T
...

Sheet 一次二次_h=m 
B1: 1. Hàm lượng xi măng (T):
B2: § 一次改良：T1 = | F2: T/m3
B3: § 二次改良：T2 = | F3: T/m3 | J3: 一次改良 | K3: m2/1T | O3: 区 分 | Q3: TNF工法[一次改良]
K4: =1/E2/E6 -> #DIV/0! | L4: 3.94 | M4: =K4/L4 -> #DIV/0! | O4: 長期許容支持力度 | Q4: Lfe = | R4: 80 | S4: kN/m2
B5: 2. Chiều dày lớp cải tạo (h): | L5: 3.94 | M5: =L5/K4 -> #DIV/0! | O5: 使用固化材 | Q5: ジオセット | R5: 200
B6: § 一次改良：h1 = | F6: m | K6: m2/2T | O6: 添加量 | Q6: 一次改良部 | R6: =E2*1000 -> 0 | S6: kg/m3 | T6: Revit
B7: § 二次改良：h2 = | F7: m | K7: =2/E2/E6 -> #DIV/0! | L7: =L4 -> 3.94 | M7: =K7/L7 -> #DIV/0! | O7: 改良厚 | Q7: H = | R7: =E6*1000 -> 0 | S7: mm | T7: 1T
B8: § 外構：h3 = | F8: m | L8: =L5 -> 3.94 | M8: =M5 -> #DIV/0! | Q8: 改良天端 GL | R8: =E10-R23 -> 0 | S8: mm | T8: 2T
K9: m2/3T | Q9: 改良下端 GL | R9: =E10-R23-R7 -> 0 | S9: mm | T9: 3T
B10: 3. Cao trình cải tạo | F10: mm | K10: =3/E2/E6 -> #DIV/0! | L10: =L4 -> 3.94 | M10: =K10/L10 -> #DIV/0! | O10: 改良面積 | Q10: 一次改良部： | R10: =ROUNDUP(F25,0) -> 0 | S10: m2 | T10: 4T
L11: =L5 -> 3.94 | M11: =M5 -> #DIV/0! | O11: 改良土量 | Q11: 一次改良部： | R11: =ROUNDUP(F28,0) -> 0 | S11: m3 | T11: 5T
B12: 4. Diện tích các lớp cải tạo (S): | K12: m2/4T | O12: 固化材使用数量 | Q12: 一次改良部： | S12: t
B13: § Tổng diện tích đất cải tạo lớp 1 | K13: =4/E2/E6 -> #DIV/0! | L13: =L4 -> 3.94 | M13: =K13/L13 -> #DIV/0! | Q13: ※ 区画割付内特記無きは 2t とする | T13: SUM | U13: =SUM(LEFT(T7,1)*U7,LEFT(T8,1)*U8,LEFT(T9,1)*U9,LEFT(T10,1)*U10,LEFT(T11,1)*U11) -> 0
B14: STT | C14: SL | D14: D | E14: R | F14: D×R | L14: =L5 -> 3.94 | M14: =M5 -> #DIV/0! | Q14: ※ ○内数値は固化材数量(t)を示す | T14: +- | U14: =I31-U13 -> 0
B15: 1 | D15: 1 | F15: =IF(C15="","",C15*D15*E15) | Q15: ※ 供試体採取箇所: 1箇所
B16: 2 | D16: 1 | F16: =IF(C16="","",C16*D16*E16)
F17: =SUM(F15:F16) -> 0
B19: § Tổng diện tích đất cải tạo lớp 2 | J19: 二次改良 | K19: m2/1T | O19: 区 分 | Q19: TNF工法[二次改良]
B20: STT | C20: SL | D20: D | E20: R | F20: D×R | K20: =1/E3/E7 -> #DIV/0! | L20: 5.51 | M20: =K20/L20 -> #DIV/0! | O20: 長期許容支持力度 | Q20: Lfe = | R20: =R4 -> 80 | S20: kN/m2
B21: 1 | D21: 1 | F21: =IF(C21="","",C21*D21*E21) | L21: 9.639 | M21: =L21/K20 -> #DIV/0! | O21: 使用固化材 | Q21: ジオセット | R21: =R5 -> 200
B22: 2 | D22: 1 | F22: =IF(C22="","",C22*D22*E22) | K22: m2/2T | O22: 添加量 | Q22: 二次改良部 | R22: =E3*1000 -> 0 | S22: kg/m3 | T22: Revit
F23: =SUM(F21:F22) -> 0 | K23: =2/E3/E7 -> #DIV/0! | L23: =L20 -> 5.51 | M23: =K23/L23 -> #DIV/0! | O23: 改良厚 | Q23: H = | R23: =E7*1000 -> 0 | S23: mm | T23: 1T
L24: =L21 -> 9.639 | M24: =M21 -> #DIV/0! | Q24: 改良天端 GL | R24: =E10 -> 0 | S24: mm | T24: 2T
B25: § 一次改良：S1 = | F25: =F17 -> 0 | G25: (m2) | K25: m2/3T | Q25: 改良下端 GL | R25: =E10-R23 -> 0 | S25: mm | T25: 3T
B26: § 二次改良：S2 = | F26: =F23 -> 0 | G26: (m2) | K26: =3/E3/E7 -> #DIV/0! | L26: =L20 -> 5.51 | M26: =K26/L26 -> #DIV/0! | O26: 改良面積 | Q26: 二次改良部： | R26: =ROUNDUP(F26,0) -> 0 | S26: m2 | T26: 4T
B27: 5. Thể tích các lớp cải tạo (V = S×h): | L27: =L21 -> 9.639 | M27: =M21 -> #DIV/0! | O27: 改良土量 | Q27: 二次改良部： | R27: =ROUNDUP(F29,0) -> 0 | S27: m3 | T27: 5T
B28: § 一次改良：Ⅴ1 = | F28: =PRODUCT(F25,E6) -> 0 | G28: (m3) | K28: m2/4T | O28: 固化材使用数量 | Q28: 二次改良部： | S28: t
B29: § 二次改良：Ⅴ2 = | F29: =PRODUCT(F26,E7) -> 0 | G29: (m3) | K29: =4/E3/E7 -> #DIV/0! | L29: =L20 -> 5.51 | M29: =K29/L29 -> #DIV/0! | Q29: ※ 区画割付内特記無きは 1t とする | T29: SUM | U29: =SUM(LEFT(T23,1)*U23,LEFT(T24,1)*U24,LEFT(T25,1)*U25,LEFT(T26,1)*U26,LEFT(T27,1)*U27) -> 0
B30: 6. Khối lượng xi măng cần thiết (N = V×T): | L30: =L21 -> 9.639 | M30: =M21 -> #DIV/0! | Q30: ※ ○内数値は固化材数量(t)を示す | T30: +- | U30: =I32-U29 -> 0
B31: § 一次改良：N1 = | F31: =PRODUCT(F28,E2) -> 0 | G31: (T) | H31: +2% | I31: =ROUNDUP(F31+F31*2%,0) -> 0 | Q31: ※ 供試体採取箇所: 1箇所
B32: § 二次改良：N2 = | F32: =PRODUCT(F29,E3) -> 0 | G32: (T) | H32: +2% | I32: =ROUNDUP(F32+F32*2%,0) -> 0
B34: 7. Diện tích Gaikou cải tạo (S):
B35: § Tổng diện tích đất Gaiko cải tạo
B36: STT | C36: SL | D36: D | E36: R | F36: D×R | J36: 外構 | K36: m2/1T | O36: 区 分 | Q36: TNF工法[外構]
B37: 1 | F37: =IF(C37="","",C37*D37*E37) | K37: =1/E3/E8 -> #DIV/0! | L37: 5.51 | M37: =K37/L37 -> #DIV/0! | O37: 長期許容支持力度 | Q37: Lfe = | R37: =R21 -> 200 | S37: kN/m2
B38: 2 | F38: =IF(C38="","",C38*D38*E38) | L38: 9.639 | M38: =L38/K37 -> #DIV/0! | O38: 使用固化材 | Q38: ジオセット | R38: =R22 -> 0
F39: =SUM(F37:F38) -> 0 | K39: m2/2T | O39: 添加量 | R39: *** | S39: kg/m3 | T39: Revit
B40: § 外構: S3= | F40: =F39 -> 0 | G40: (m2) | K40: =2/E3/E8 -> #DIV/0! | L40: =L37 -> 5.51 | M40: =K40/L40 -> #DIV/0! | O40: 改良厚 | R40: *** | S40: mm | T40: 1T
B41: § 外構: V3= | F41: =PRODUCT(F40,E8) -> 0 | G41: (m3) | L41: =L38 -> 9.639 | M41: =M38 -> #DIV/0! | Q41: 改良天端 GL | R41: *** | S41: mm | T41: 2T
B42: § 外構: N3= | F42: =F41*E3 -> 0 | G42: (T) | H42: +2% | I42: =ROUNDUP(F42+F42*2%,0) -> 0 | K42: m2/3T | Q42: 改良下端 GL | R42: *** | S42: mm | T42: 3T
...

Sheet 一次二次_h2=0.8m
B1: 1. Hàm lượng xi măng (T):
B2: § 一次改良：T1 = | E2: 0.15 | F2: T/m3
B3: § 二次改良：T2 = | F3: T/m3 | J3: 一次改良 | K3: m2/1T | O3: 区 分 | Q3: TNF工法[一次改良]
K4: =1/E2/E6 -> 8.3333333 | L4: 2 | M4: =K4/L4 -> 4.1666667 | O4: 長期許容支持力度 | Q4: Lfe = | R4: 80 | S4: kN/m2
B5: 2. Chiều dày lớp cải tạo (h): | L5: 22.074 | M5: =L5/K4 -> 2.64888 | O5: 使用固化材 | Q5: ジオセット | R5: 200
B6: § 一次改良：h1 = | E6: 0.8 | F6: m | K6: m2/2T | O6: 添加量 | Q6: 一次改良部 | R6: =E2*1000 -> 150 | S6: kg/m3 | T6: Revit
B7: § 二次改良：h2 = | F7: m | K7: =2/E2/E6 -> 16.666667 | L7: =L4 -> 2 | M7: =K7/L7 -> 8.3333333 | O7: 改良厚 | Q7: H = | R7: =E6*1000 -> 800 | S7: mm | T7: 1T
B8: § 外構：h3 = | F8: m | L8: =L5 -> 22.074 | M8: =M5 -> 2.64888 | Q8: 改良天端 GL | R8: =E10-R23 -> 0 | S8: mm | T8: 2T
K9: m2/3T | Q9: 改良下端 GL | R9: =E10-R23-R7 -> -800 | S9: mm | T9: 3T
B10: 3. Cao trình cải tạo | F10: mm | K10: =3/E2/E6 -> 25 | L10: =L4 -> 2 | M10: =K10/L10 -> 12.5 | O10: 改良面積 | Q10: 一次改良部： | R10: =ROUNDUP(F25,0) -> 97 | S10: m2 | T10: 4T
L11: =L5 -> 22.074 | M11: =M5 -> 2.64888 | O11: 改良土量 | Q11: 一次改良部： | R11: =ROUNDUP(F28,0) -> 78 | S11: m3 | T11: 5T
B12: 4. Diện tích các lớp cải tạo (S): | K12: m2/4T | O12: 固化材使用数量 | Q12: 一次改良部： | S12: t
B13: § Tổng diện tích đất cải tạo lớp 1 | K13: =4/E2/E6 -> 33.333333 | L13: =L4 -> 2 | M13: =K13/L13 -> 16.666667 | Q13: ※ 区画割付内特記無きは 2t とする | T13: SUM | U13: =SUM(LEFT(T7,1)*U7,LEFT(T8,1)*U8,LEFT(T9,1)*U9,LEFT(T10,1)*U10,LEFT(T11,1)*U11) -> 0
B14: STT | C14: SL | D14: D | E14: R | F14: D×R | L14: =L5 -> 22.074 | M14: =M5 -> 2.64888 | Q14: ※ ○内数値は固化材数量(t)を示す | T14: +- | U14: =I31-U13 -> 12
B15: 1 | C15: 1 | D15: 1 | E15: 96.924 | F15: =IF(C15="","",C15*D15*E15) -> 96.924 | Q15: ※ 供試体採取箇所: 1箇所
B16: 2 | D16: 1 | F16: =IF(C16="","",C16*D16*E16)
F17: =SUM(F15:F16) -> 96.924
B19: § Tổng diện tích đất cải tạo lớp 2 | J19: 二次改良 | K19: m2/1T | O19: 区 分 | Q19: TNF工法[二次改良]
B20: STT | C20: SL | D20: D | E20: R | F20: D×R | K20: =1/E3/E7 -> #DIV/0! | L20: 5.51 | M20: =K20/L20 -> #DIV/0! | O20: 長期許容支持力度 | Q20: Lfe = | R20: =R4 -> 80 | S20: kN/m2
B21: 1 | D21: 1 | F21: =IF(C21="","",C21*D21*E21) | L21: 9.639 | M21: =L21/K20 -> #DIV/0! | O21: 使用固化材 | Q21: ジオセット | R21: =R5 -> 200
B22: 2 | D22: 1 | F22: =IF(C22="","",C22*D22*E22) | K22: m2/2T | O22: 添加量 | Q22: 二次改良部 | R22: =E3*1000 -> 0 | S22: kg/m3 | T22: Revit
F23: =SUM(F21:F22) -> 0 | K23: =2/E3/E7 -> #DIV/0! | L23: =L20 -> 5.51 | M23: =K23/L23 -> #DIV/0! | O23: 改良厚 | Q23: H = | R23: =E7*1000 -> 0 | S23: mm | T23: 1T
L24: =L21 -> 9.639 | M24: =M21 -> #DIV/0! | Q24: 改良天端 GL | R24: =E10 -> 0 | S24: mm | T24: 2T
B25: § 一次改良：S1 = | F25: =F17 -> 96.924 | G25: (m2) | K25: m2/3T | Q25: 改良下端 GL | R25: =E10-R23 -> 0 | S25: mm | T25: 3T
B26: § 二次改良：S2 = | F26: =F23 -> 0 | G26: (m2) | K26: =3/E3/E7 -> #DIV/0! | L26: =L20 -> 5.51 | M26: =K26/L26 -> #DIV/0! | O26: 改良面積 | Q26: 二次改良部： | R26: =ROUNDUP(F26,0) -> 0 | S26: m2 | T26: 4T
B27: 5. Thể tích các lớp cải tạo (V = S×h): | L27: =L21 -> 9.639 | M27: =M21 -> #DIV/0! | O27: 改良土量 | Q27: 二次改良部： | R27: =ROUNDUP(F29,0) -> 0 | S27: m3 | T27: 5T
B28: § 一次改良：Ⅴ1 = | F28: =PRODUCT(F25,E6) -> 77.5392 | G28: (m3) | K28: m2/4T | O28: 固化材使用数量 | Q28: 二次改良部： | S28: t
B29: § 二次改良：Ⅴ2 = | F29: =PRODUCT(F26,E7) -> 0 | G29: (m3) | K29: =4/E3/E7 -> #DIV/0! | L29: =L20 -> 5.51 | M29: =K29/L29 -> #DIV/0! | Q29: ※ 区画割付内特記無きは 1t とする | T29: SUM | U29: =SUM(LEFT(T23,1)*U23,LEFT(T24,1)*U24,LEFT(T25,1)*U25,LEFT(T26,1)*U26,LEFT(T27,1)*U27) -> 0
B30: 6. Khối lượng xi măng cần thiết (N = V×T): | L30: =L21 -> 9.639 | M30: =M21 -> #DIV/0! | Q30: ※ ○内数値は固化材数量(t)を示す | T30: +- | U30: =I32-U29 -> 0
B31: § 一次改良：N1 = | F31: =PRODUCT(F28,E2) -> 11.63088 | G31: (T) | H31: +2% | I31: =ROUNDUP(F31+F31*2%,0) -> 12 | Q31: ※ 供試体採取箇所: 1箇所
B32: § 二次改良：N2 = | F32: =PRODUCT(F29,E3) -> 0 | G32: (T) | H32: +2% | I32: =ROUNDUP(F32+F32*2%,0) -> 0
B34: 7. Diện tích Gaikou cải tạo (S):
B35: § Tổng diện tích đất Gaiko cải tạo
B36: STT | C36: SL | D36: D | E36: R | F36: D×R | J36: 外構 | K36: m2/1T | O36: 区 分 | Q36: TNF工法[外構]
B37: 1 | F37: =IF(C37="","",C37*D37*E37) | K37: =1/E3/E8 -> #DIV/0! | L37: 5.51 | M37: =K37/L37 -> #DIV/0! | O37: 長期許容支持力度 | Q37: Lfe = | R37: =R21 -> 200 | S37: kN/m2
B38: 2 | F38: =IF(C38="","",C38*D38*E38) | L38: 9.639 | M38: =L38/K37 -> #DIV/0! | O38: 使用固化材 | Q38: ジオセット | R38: =R22 -> 0
F39: =SUM(F37:F38) -> 0 | K39: m2/2T | O39: 添加量 | R39: *** | S39: kg/m3 | T39: Revit
B40: § 外構: S3= | F40: =F39 -> 0 | G40: (m2) | K40: =2/E3/E8 -> #DIV/0! | L40: =L37 -> 5.51 | M40: =K40/L40 -> #DIV/0! | O40: 改良厚 | R40: *** | S40: mm | T40: 1T
B41: § 外構: V3= | F41: =PRODUCT(F40,E8) -> 0 | G41: (m3) | L41: =L38 -> 9.639 | M41: =M38 -> #DIV/0! | Q41: 改良天端 GL | R41: *** | S41: mm | T41: 2T
B42: § 外構: N3= | F42: =F41*E3 -> 0 | G42: (T) | H42: +2% | I42: =ROUNDUP(F42+F42*2%,0) -> 0 | K42: m2/3T | Q42: 改良下端 GL | R42: *** | S42: mm | T42: 3T
...

Sheet 一次二次_h=0.7m
B1: 1. Hàm lượng xi măng (T):
B2: § 一次改良：T1 = | E2: 0.15 | F2: T/m3
B3: § 二次改良：T2 = | F3: T/m3 | J3: 一次改良 | K3: m2/1T | O3: 区 分 | Q3: TNF工法[一次改良]
K4: =1/E2/E6 -> 9.5238095 | L4: 2 | M4: =K4/L4 -> 4.7619048 | O4: 長期許容支持力度 | Q4: Lfe = | R4: 80 | S4: kN/m2
B5: 2. Chiều dày lớp cải tạo (h): | L5: 43.63 | M5: =L5/K4 -> 4.58115 | O5: 使用固化材 | Q5: ジオセット | R5: 200
B6: § 一次改良：h1 = | E6: 0.7 | F6: m | K6: m2/2T | O6: 添加量 | Q6: 一次改良部 | R6: =E2*1000 -> 150 | S6: kg/m3 | T6: Revit
B7: § 二次改良：h2 = | F7: m | K7: =2/E2/E6 -> 19.047619 | L7: =L4 -> 2 | M7: =K7/L7 -> 9.5238095 | O7: 改良厚 | Q7: H = | R7: =E6*1000 -> 700 | S7: mm | T7: 1T
B8: § 外構：h3 = | F8: m | L8: =L5 -> 43.63 | M8: =M5 -> 4.58115 | Q8: 改良天端 GL | R8: =E10-R23 -> 0 | S8: mm | T8: 2T
K9: m2/3T | Q9: 改良下端 GL | R9: =E10-R23-R7 -> -700 | S9: mm | T9: 3T
B10: 3. Cao trình cải tạo | F10: mm | K10: =3/E2/E6 -> 28.571429 | L10: =L4 -> 2 | M10: =K10/L10 -> 14.285714 | O10: 改良面積 | Q10: 一次改良部： | R10: =ROUNDUP(F25,0) -> 171 | S10: m2 | T10: 4T
I11: =5/E2/E6 -> 47.619048 | L11: =L5 -> 43.63 | M11: =M5 -> 4.58115 | O11: 改良土量 | Q11: 一次改良部： | R11: =ROUNDUP(F28,0) -> 120 | S11: m3 | T11: 5T
B12: 4. Diện tích các lớp cải tạo (S): | K12: m2/4T | O12: 固化材使用数量 | Q12: 一次改良部： | S12: t
B13: § Tổng diện tích đất cải tạo lớp 1 | K13: =4/E2/E6 -> 38.095238 | L13: =L4 -> 2 | M13: =K13/L13 -> 19.047619 | Q13: ※ 区画割付内特記無きは 2t とする | T13: SUM | U13: =SUM(LEFT(T7,1)*U7,LEFT(T8,1)*U8,LEFT(T9,1)*U9,LEFT(T10,1)*U10,LEFT(T11,1)*U11) -> 0
B14: STT | C14: SL | D14: D | E14: R | F14: D×R | L14: =L5 -> 43.63 | M14: =M5 -> 4.58115 | Q14: ※ ○内数値は固化材数量(t)を示す | T14: +- | U14: =I31-U13 -> 19
B15: 1 | C15: 1 | D15: 1 | E15: 170.63 | F15: =IF(C15="","",C15*D15*E15) -> 170.63 | Q15: ※ 供試体採取箇所: 1箇所
B16: 2 | D16: 1 | F16: =IF(C16="","",C16*D16*E16)
F17: =SUM(F15:F16) -> 170.63
B19: § Tổng diện tích đất cải tạo lớp 2 | J19: 二次改良 | K19: m2/1T | O19: 区 分 | Q19: TNF工法[二次改良]
B20: STT | C20: SL | D20: D | E20: R | F20: D×R | K20: =1/E3/E7 -> #DIV/0! | L20: 5.51 | M20: =K20/L20 -> #DIV/0! | O20: 長期許容支持力度 | Q20: Lfe = | R20: =R4 -> 80 | S20: kN/m2
B21: 1 | D21: 1 | F21: =IF(C21="","",C21*D21*E21) | L21: 9.639 | M21: =L21/K20 -> #DIV/0! | O21: 使用固化材 | Q21: ジオセット | R21: =R5 -> 200
B22: 2 | D22: 1 | F22: =IF(C22="","",C22*D22*E22) | K22: m2/2T | O22: 添加量 | Q22: 二次改良部 | R22: =E3*1000 -> 0 | S22: kg/m3 | T22: Revit
F23: =SUM(F21:F22) -> 0 | K23: =2/E3/E7 -> #DIV/0! | L23: =L20 -> 5.51 | M23: =K23/L23 -> #DIV/0! | O23: 改良厚 | Q23: H = | R23: =E7*1000 -> 0 | S23: mm | T23: 1T
L24: =L21 -> 9.639 | M24: =M21 -> #DIV/0! | Q24: 改良天端 GL | R24: =E10 -> 0 | S24: mm | T24: 2T
B25: § 一次改良：S1 = | F25: =F17 -> 170.63 | G25: (m2) | K25: m2/3T | Q25: 改良下端 GL | R25: =E10-R23 -> 0 | S25: mm | T25: 3T
B26: § 二次改良：S2 = | F26: =F23 -> 0 | G26: (m2) | K26: =3/E3/E7 -> #DIV/0! | L26: =L20 -> 5.51 | M26: =K26/L26 -> #DIV/0! | O26: 改良面積 | Q26: 二次改良部： | R26: =ROUNDUP(F26,0) -> 0 | S26: m2 | T26: 4T
B27: 5. Thể tích các lớp cải tạo (V = S×h): | L27: =L21 -> 9.639 | M27: =M21 -> #DIV/0! | O27: 改良土量 | Q27: 二次改良部： | R27: =ROUNDUP(F29,0) -> 0 | S27: m3 | T27: 5T
B28: § 一次改良：Ⅴ1 = | F28: =PRODUCT(F25,E6) -> 119.441 | G28: (m3) | K28: m2/4T | O28: 固化材使用数量 | Q28: 二次改良部： | S28: t
B29: § 二次改良：Ⅴ2 = | F29: =PRODUCT(F26,E7) -> 0 | G29: (m3) | K29: =4/E3/E7 -> #DIV/0! | L29: =L20 -> 5.51 | M29: =K29/L29 -> #DIV/0! | Q29: ※ 区画割付内特記無きは 1t とする | T29: SUM | U29: =SUM(LEFT(T23,1)*U23,LEFT(T24,1)*U24,LEFT(T25,1)*U25,LEFT(T26,1)*U26,LEFT(T27,1)*U27) -> 0
B30: 6. Khối lượng xi măng cần thiết (N = V×T): | L30: =L21 -> 9.639 | M30: =M21 -> #DIV/0! | Q30: ※ ○内数値は固化材数量(t)を示す | T30: +- | U30: =I32-U29 -> 0
B31: § 一次改良：N1 = | F31: =PRODUCT(F28,E2) -> 17.91615 | G31: (T) | H31: +2% | I31: =ROUNDUP(F31+F31*2%,0) -> 19 | Q31: ※ 供試体採取箇所: 1箇所
B32: § 二次改良：N2 = | F32: =PRODUCT(F29,E3) -> 0 | G32: (T) | H32: +2% | I32: =ROUNDUP(F32+F32*2%,0) -> 0
B34: 7. Diện tích Gaikou cải tạo (S):
B35: § Tổng diện tích đất Gaiko cải tạo
B36: STT | C36: SL | D36: D | E36: R | F36: D×R | J36: 外構 | K36: m2/1T | O36: 区 分 | Q36: TNF工法[外構]
B37: 1 | F37: =IF(C37="","",C37*D37*E37) | K37: =1/E3/E8 -> #DIV/0! | L37: 5.51 | M37: =K37/L37 -> #DIV/0! | O37: 長期許容支持力度 | Q37: Lfe = | R37: =R21 -> 200 | S37: kN/m2
B38: 2 | F38: =IF(C38="","",C38*D38*E38) | L38: 9.639 | M38: =L38/K37 -> #DIV/0! | O38: 使用固化材 | Q38: ジオセット | R38: =R22 -> 0
F39: =SUM(F37:F38) -> 0 | K39: m2/2T | O39: 添加量 | R39: *** | S39: kg/m3 | T39: Revit
B40: § 外構: S3= | F40: =F39 -> 0 | G40: (m2) | K40: =2/E3/E8 -> #DIV/0! | L40: =L37 -> 5.51 | M40: =K40/L40 -> #DIV/0! | O40: 改良厚 | R40: *** | S40: mm | T40: 1T
B41: § 外構: V3= | F41: =PRODUCT(F40,E8) -> 0 | G41: (m3) | L41: =L38 -> 9.639 | M41: =M38 -> #DIV/0! | Q41: 改良天端 GL | R41: *** | S41: mm | T41: 2T
B42: § 外構: N3= | F42: =F41*E3 -> 0 | G42: (T) | H42: +2% | I42: =ROUNDUP(F42+F42*2%,0) -> 0 | K42: m2/3T | Q42: 改良下端 GL | R42: *** | S42: mm | T42: 3T
...

Sheet 一次二次_h=0.5m 
B1: 1. Hàm lượng xi măng (T):
B2: § 一次改良：T1 = | E2: 0.15 | F2: T/m3
B3: § 二次改良：T2 = | F3: T/m3 | J3: 一次改良 | K3: m2/1T | O3: 区 分 | Q3: TNF工法[一次改良]
K4: =1/E2/E6 -> 13.333333 | L4: 2 | M4: =K4/L4 -> 6.6666667 | O4: 長期許容支持力度 | Q4: Lfe = | R4: 80 | S4: kN/m2
B5: 2. Chiều dày lớp cải tạo (h): | L5: 20.35 | M5: =L5/K4 -> 1.52625 | O5: 使用固化材 | Q5: ジオセット | R5: 200
B6: § 一次改良：h1 = | E6: 0.5 | F6: m | K6: m2/2T | O6: 添加量 | Q6: 一次改良部 | R6: =E2*1000 -> 150 | S6: kg/m3 | T6: Revit
B7: § 二次改良：h2 = | F7: m | K7: =2/E2/E6 -> 26.666667 | L7: =L4 -> 2 | M7: =K7/L7 -> 13.333333 | O7: 改良厚 | Q7: H = | R7: =E6*1000 -> 500 | S7: mm | T7: 1T
B8: § 外構：h3 = | F8: m | L8: =L5 -> 20.35 | M8: =M5 -> 1.52625 | Q8: 改良天端 GL | R8: =E10-R23 -> 0 | S8: mm | T8: 2T
K9: m2/3T | Q9: 改良下端 GL | R9: =E10-R23-R7 -> -500 | S9: mm | T9: 3T
B10: 3. Cao trình cải tạo | F10: mm | K10: =3/E2/E6 -> 40 | L10: =L4 -> 2 | M10: =K10/L10 -> 20 | O10: 改良面積 | Q10: 一次改良部： | R10: =ROUNDUP(F25,0) -> 83 | S10: m2 | T10: 4T
L11: =L5 -> 20.35 | M11: =M5 -> 1.52625 | O11: 改良土量 | Q11: 一次改良部： | R11: =ROUNDUP(F28,0) -> 42 | S11: m3 | T11: 5T
B12: 4. Diện tích các lớp cải tạo (S): | K12: m2/4T | O12: 固化材使用数量 | Q12: 一次改良部： | S12: t
B13: § Tổng diện tích đất cải tạo lớp 1 | K13: =4/E2/E6 -> 53.333333 | L13: =L4 -> 2 | M13: =K13/L13 -> 26.666667 | Q13: ※ 区画割付内特記無きは 2t とする | T13: SUM | U13: =SUM(LEFT(T7,1)*U7,LEFT(T8,1)*U8,LEFT(T9,1)*U9,LEFT(T10,1)*U10,LEFT(T11,1)*U11) -> 0
B14: STT | C14: SL | D14: D | E14: R | F14: D×R | L14: =L5 -> 20.35 | M14: =M5 -> 1.52625 | Q14: ※ ○内数値は固化材数量(t)を示す | T14: +- | U14: =I31-U13 -> 7
B15: 1 | C15: 1 | D15: 1 | E15: 82.55 | F15: =IF(C15="","",C15*D15*E15) -> 82.55 | Q15: ※ 供試体採取箇所: 1箇所
B16: 2 | D16: 1 | F16: =IF(C16="","",C16*D16*E16)
F17: =SUM(F15:F16) -> 82.55
B19: § Tổng diện tích đất cải tạo lớp 2 | J19: 二次改良 | K19: m2/1T | O19: 区 分 | Q19: TNF工法[二次改良]
B20: STT | C20: SL | D20: D | E20: R | F20: D×R | K20: =1/E3/E7 -> #DIV/0! | L20: 5.51 | M20: =K20/L20 -> #DIV/0! | O20: 長期許容支持力度 | Q20: Lfe = | R20: =R4 -> 80 | S20: kN/m2
B21: 1 | D21: 1 | F21: =IF(C21="","",C21*D21*E21) | L21: 9.639 | M21: =L21/K20 -> #DIV/0! | O21: 使用固化材 | Q21: ジオセット | R21: =R5 -> 200
B22: 2 | D22: 1 | F22: =IF(C22="","",C22*D22*E22) | K22: m2/2T | O22: 添加量 | Q22: 二次改良部 | R22: =E3*1000 -> 0 | S22: kg/m3 | T22: Revit
F23: =SUM(F21:F22) -> 0 | K23: =2/E3/E7 -> #DIV/0! | L23: =L20 -> 5.51 | M23: =K23/L23 -> #DIV/0! | O23: 改良厚 | Q23: H = | R23: =E7*1000 -> 0 | S23: mm | T23: 1T
L24: =L21 -> 9.639 | M24: =M21 -> #DIV/0! | Q24: 改良天端 GL | R24: =E10 -> 0 | S24: mm | T24: 2T
B25: § 一次改良：S1 = | F25: =F17 -> 82.55 | G25: (m2) | K25: m2/3T | Q25: 改良下端 GL | R25: =E10-R23 -> 0 | S25: mm | T25: 3T
B26: § 二次改良：S2 = | F26: =F23 -> 0 | G26: (m2) | K26: =3/E3/E7 -> #DIV/0! | L26: =L20 -> 5.51 | M26: =K26/L26 -> #DIV/0! | O26: 改良面積 | Q26: 二次改良部： | R26: =ROUNDUP(F26,0) -> 0 | S26: m2 | T26: 4T
B27: 5. Thể tích các lớp cải tạo (V = S×h): | L27: =L21 -> 9.639 | M27: =M21 -> #DIV/0! | O27: 改良土量 | Q27: 二次改良部： | R27: =ROUNDUP(F29,0) -> 0 | S27: m3 | T27: 5T
B28: § 一次改良：Ⅴ1 = | F28: =PRODUCT(F25,E6) -> 41.275 | G28: (m3) | K28: m2/4T | O28: 固化材使用数量 | Q28: 二次改良部： | S28: t
B29: § 二次改良：Ⅴ2 = | F29: =PRODUCT(F26,E7) -> 0 | G29: (m3) | K29: =4/E3/E7 -> #DIV/0! | L29: =L20 -> 5.51 | M29: =K29/L29 -> #DIV/0! | Q29: ※ 区画割付内特記無きは 1t とする | T29: SUM | U29: =SUM(LEFT(T23,1)*U23,LEFT(T24,1)*U24,LEFT(T25,1)*U25,LEFT(T26,1)*U26,LEFT(T27,1)*U27) -> 0
B30: 6. Khối lượng xi măng cần thiết (N = V×T): | L30: =L21 -> 9.639 | M30: =M21 -> #DIV/0! | Q30: ※ ○内数値は固化材数量(t)を示す | T30: +- | U30: =I32-U29 -> 0
B31: § 一次改良：N1 = | F31: =PRODUCT(F28,E2) -> 6.19125 | G31: (T) | H31: +2% | I31: =ROUNDUP(F31+F31*2%,0) -> 7 | Q31: ※ 供試体採取箇所: 1箇所
B32: § 二次改良：N2 = | F32: =PRODUCT(F29,E3) -> 0 | G32: (T) | H32: +2% | I32: =ROUNDUP(F32+F32*2%,0) -> 0
B34: 7. Diện tích Gaikou cải tạo (S):
B35: § Tổng diện tích đất Gaiko cải tạo
B36: STT | C36: SL | D36: D | E36: R | F36: D×R | J36: 外構 | K36: m2/1T | O36: 区 分 | Q36: TNF工法[外構]
B37: 1 | F37: =IF(C37="","",C37*D37*E37) | K37: =1/E3/E8 -> #DIV/0! | L37: 5.51 | M37: =K37/L37 -> #DIV/0! | O37: 長期許容支持力度 | Q37: Lfe = | R37: =R21 -> 200 | S37: kN/m2
B38: 2 | F38: =IF(C38="","",C38*D38*E38) | L38: 9.639 | M38: =L38/K37 -> #DIV/0! | O38: 使用固化材 | Q38: ジオセット | R38: =R22 -> 0
F39: =SUM(F37:F38) -> 0 | K39: m2/2T | O39: 添加量 | R39: *** | S39: kg/m3 | T39: Revit
B40: § 外構: S3= | F40: =F39 -> 0 | G40: (m2) | K40: =2/E3/E8 -> #DIV/0! | L40: =L37 -> 5.51 | M40: =K40/L40 -> #DIV/0! | O40: 改良厚 | R40: *** | S40: mm | T40: 1T
B41: § 外構: V3= | F41: =PRODUCT(F40,E8) -> 0 | G41: (m3) | L41: =L38 -> 9.639 | M41: =M38 -> #DIV/0! | Q41: 改良天端 GL | R41: *** | S41: mm | T41: 2T
B42: § 外構: N3= | F42: =F41*E3 -> 0 | G42: (T) | H42: +2% | I42: =ROUNDUP(F42+F42*2%,0) -> 0 | K42: m2/3T | Q42: 改良下端 GL | R42: *** | S42: mm | T42: 3T
...

Sheet 掘削深度_Templete
B1: Dự Án | C1: 20230044 | J1: Input | K1: Com Caculus
B2: 1. Cao trình mặt đất cải tạo | D2: GL | F2: mm | G2: Vùng 1
D3: =IF(D2="","",D2) -> GL | F3: mm | G3: Vùng 2
D4: =IF(D2="","",D2) -> GL | F4: mm | G4: Vùng 3
D5: =IF(D2="","",D2) -> GL | F5: mm | G5: Vùng 4
D6: =IF(D2="","",D2) -> GL | F6: mm | G6: Vùng 5
B7: 2. Thông số kích thước hố đào móng:
B8: - Bảng chi tiết các loại hố đào móng:
A9: Zone | B9: STT | C9: Tên Móng | D9: Loại Móng | E9: Bê tông lót | F9: Cao độ mặt trên cấu kiện (H1) | G9: Cao độ mặt trên cấu kiện (H2>H1) | H9: Chiều cao cấu kiện (D) | I9: Chiều cao (D2) Daike | J9: Cao độ mặt dưới Đào đất+BT Lót | K9: Chiều cao đào đất + BT Lót | L9: Khoảng mở rộng | M9: Copy text to revit | N9: Copy text to revit Daike | O9: Copy text to revit Daike Daike | P9: Check đào hay không
E10: =IF(C10="","",VLOOKUP(D10,データ!$A$2:$B$12,2,0)) | J10: =IF(C10="","",F10-H10-E10) | K10: =IF(C10="","",IF(A10=1,$E$2-J10,IF(A10=2,$E$3-J10,IF(A10=3,$E$4-J10,IF(A10=4,$E$5-J10,$E$6-J10))))) | L10: =IF(C10="","",IF(D10="TNF-D",50,IF(D10="TNF-DD",50,IF(D10="FW/FG",100,(IF(ABS(K10)>800,100,50)))))) | M10: =IF(C10="","",IF(RIGHT(D10,4)="スロープ",CONCATENATE($D$2," ",TEXT(G10-H10-E10,"#,##0_ "),"mm→",TEXT(J10,"#,##0_ "),"mm (",C10,")"," (余掘: ",L10,"mm)"),IF(D10="TNF-D",CONCATENATE($D$2," ",TEXT(J10,"#,##0_ "),"mm (",C10,"の底面)"),IF(D10="TNF-DD",CONCATENATE($D$2," ",TEXT(J10,"#,##0_ "),"mm (",C10,"の底面)"),CONCATENATE($D$2," ",TEXT(J10,"#,##0_ "),"mm (",C10,")"," (余掘: ",L10,"mm)"))))) | N10: =IF(C10="","",IF(D10="TNF-D",CONCATENATE($D$2," ",TEXT(F10-I10,"#,##0_ "),"mm→",TEXT(J10,"#,##0_ "),"mm (",C10,"の法面)"),IF(D10="TNF-DD",CONCATENATE($D$2," ",TEXT(F10-I10-50,"#,##0_ "),"mm→",TEXT(J10,"#,##0_ "),"mm (",C10,"の法面)"),"*"))) | O10: =IF(C10="","",IF(D10="TNF-DD",CONCATENATE($D$2," ",TEXT(F10-I10-50,"#,##0_ "),"mm (",C10,"の基礎外周)"," (余掘: 50mm)"),"*")) | P10: =IF(K10>0," ","Dont need to dig")
E11: =IF(C11="","",VLOOKUP(D11,データ!$A$2:$B$12,2,0)) | J11: =IF(C11="","",F11-H11-E11) | K11: =IF(C11="","",IF(A11=1,$E$2-J11,IF(A11=2,$E$3-J11,IF(A11=3,$E$4-J11,IF(A11=4,$E$5-J11,$E$6-J11))))) | L11: =IF(C11="","",IF(D11="TNF-D",50,IF(D11="TNF-DD",50,IF(D11="FW/FG",100,(IF(ABS(K11)>800,100,50)))))) | M11: =IF(C11="","",IF(RIGHT(D11,4)="スロープ",CONCATENATE($D$2," ",TEXT(G11-H11-E11,"#,##0_ "),"mm→",TEXT(J11,"#,##0_ "),"mm (",C11,")"," (余掘: ",L11,"mm)"),IF(D11="TNF-D",CONCATENATE($D$2," ",TEXT(J11,"#,##0_ "),"mm (",C11,"の底面)"),IF(D11="TNF-DD",CONCATENATE($D$2," ",TEXT(J11,"#,##0_ "),"mm (",C11,"の底面)"),CONCATENATE($D$2," ",TEXT(J11,"#,##0_ "),"mm (",C11,")"," (余掘: ",L11,"mm)"))))) | N11: =IF(C11="","",IF(D11="TNF-D",CONCATENATE($D$2," ",TEXT(F11-I11,"#,##0_ "),"mm→",TEXT(J11,"#,##0_ "),"mm (",C11,"の法面)"),IF(D11="TNF-DD",CONCATENATE($D$2," ",TEXT(F11-I11-50,"#,##0_ "),"mm→",TEXT(J11,"#,##0_ "),"mm (",C11,"の法面)"),"*"))) | O11: =IF(C11="","",IF(D11="TNF-DD",CONCATENATE($D$2," ",TEXT(F11-I11-50,"#,##0_ "),"mm (",C11,"の基礎外周)"," (余掘: 50mm)"),"*")) | P11: =IF(K11>0," ","Dont need to dig")
E12: =IF(C12="","",VLOOKUP(D12,データ!$A$2:$B$12,2,0)) | J12: =IF(C12="","",F12-H12-E12) | K12: =IF(C12="","",IF(A12=1,$E$2-J12,IF(A12=2,$E$3-J12,IF(A12=3,$E$4-J12,IF(A12=4,$E$5-J12,$E$6-J12))))) | L12: =IF(C12="","",IF(D12="TNF-D",50,IF(D12="TNF-DD",50,IF(D12="FW/FG",100,(IF(ABS(K12)>800,100,50)))))) | M12: =IF(C12="","",IF(RIGHT(D12,4)="スロープ",CONCATENATE($D$2," ",TEXT(G12-H12-E12,"#,##0_ "),"mm→",TEXT(J12,"#,##0_ "),"mm (",C12,")"," (余掘: ",L12,"mm)"),IF(D12="TNF-D",CONCATENATE($D$2," ",TEXT(J12,"#,##0_ "),"mm (",C12,"の底面)"),IF(D12="TNF-DD",CONCATENATE($D$2," ",TEXT(J12,"#,##0_ "),"mm (",C12,"の底面)"),CONCATENATE($D$2," ",TEXT(J12,"#,##0_ "),"mm (",C12,")"," (余掘: ",L12,"mm)"))))) | N12: =IF(C12="","",IF(D12="TNF-D",CONCATENATE($D$2," ",TEXT(F12-I12,"#,##0_ "),"mm→",TEXT(J12,"#,##0_ "),"mm (",C12,"の法面)"),IF(D12="TNF-DD",CONCATENATE($D$2," ",TEXT(F12-I12-50,"#,##0_ "),"mm→",TEXT(J12,"#,##0_ "),"mm (",C12,"の法面)"),"*"))) | O12: =IF(C12="","",IF(D12="TNF-DD",CONCATENATE($D$2," ",TEXT(F12-I12-50,"#,##0_ "),"mm (",C12,"の基礎外周)"," (余掘: 50mm)"),"*")) | P12: =IF(K12>0," ","Dont need to dig")
E13: =IF(C13="","",VLOOKUP(D13,データ!$A$2:$B$12,2,0)) | J13: =IF(C13="","",F13-H13-E13) | K13: =IF(C13="","",IF(A13=1,$E$2-J13,IF(A13=2,$E$3-J13,IF(A13=3,$E$4-J13,IF(A13=4,$E$5-J13,$E$6-J13))))) | L13: =IF(C13="","",IF(D13="TNF-D",50,IF(D13="TNF-DD",50,IF(D13="FW/FG",100,(IF(ABS(K13)>800,100,50)))))) | M13: =IF(C13="","",IF(RIGHT(D13,4)="スロープ",CONCATENATE($D$2," ",TEXT(G13-H13-E13,"#,##0_ "),"mm→",TEXT(J13,"#,##0_ "),"mm (",C13,")"," (余掘: ",L13,"mm)"),IF(D13="TNF-D",CONCATENATE($D$2," ",TEXT(J13,"#,##0_ "),"mm (",C13,"の底面)"),IF(D13="TNF-DD",CONCATENATE($D$2," ",TEXT(J13,"#,##0_ "),"mm (",C13,"の底面)"),CONCATENATE($D$2," ",TEXT(J13,"#,##0_ "),"mm (",C13,")"," (余掘: ",L13,"mm)"))))) | N13: =IF(C13="","",IF(D13="TNF-D",CONCATENATE($D$2," ",TEXT(F13-I13,"#,##0_ "),"mm→",TEXT(J13,"#,##0_ "),"mm (",C13,"の法面)"),IF(D13="TNF-DD",CONCATENATE($D$2," ",TEXT(F13-I13-50,"#,##0_ "),"mm→",TEXT(J13,"#,##0_ "),"mm (",C13,"の法面)"),"*"))) | O13: =IF(C13="","",IF(D13="TNF-DD",CONCATENATE($D$2," ",TEXT(F13-I13-50,"#,##0_ "),"mm (",C13,"の基礎外周)"," (余掘: 50mm)"),"*")) | P13: =IF(K13>0," ","Dont need to dig")
E14: =IF(C14="","",VLOOKUP(D14,データ!$A$2:$B$12,2,0)) | J14: =IF(C14="","",F14-H14-E14) | K14: =IF(C14="","",IF(A14=1,$E$2-J14,IF(A14=2,$E$3-J14,IF(A14=3,$E$4-J14,IF(A14=4,$E$5-J14,$E$6-J14))))) | L14: =IF(C14="","",IF(D14="TNF-D",50,IF(D14="TNF-DD",50,IF(D14="FW/FG",100,(IF(ABS(K14)>800,100,50)))))) | M14: =IF(C14="","",IF(RIGHT(D14,4)="スロープ",CONCATENATE($D$2," ",TEXT(G14-H14-E14,"#,##0_ "),"mm→",TEXT(J14,"#,##0_ "),"mm (",C14,")"," (余掘: ",L14,"mm)"),IF(D14="TNF-D",CONCATENATE($D$2," ",TEXT(J14,"#,##0_ "),"mm (",C14,"の底面)"),IF(D14="TNF-DD",CONCATENATE($D$2," ",TEXT(J14,"#,##0_ "),"mm (",C14,"の底面)"),CONCATENATE($D$2," ",TEXT(J14,"#,##0_ "),"mm (",C14,")"," (余掘: ",L14,"mm)"))))) | N14: =IF(C14="","",IF(D14="TNF-D",CONCATENATE($D$2," ",TEXT(F14-I14,"#,##0_ "),"mm→",TEXT(J14,"#,##0_ "),"mm (",C14,"の法面)"),IF(D14="TNF-DD",CONCATENATE($D$2," ",TEXT(F14-I14-50,"#,##0_ "),"mm→",TEXT(J14,"#,##0_ "),"mm (",C14,"の法面)"),"*"))) | O14: =IF(C14="","",IF(D14="TNF-DD",CONCATENATE($D$2," ",TEXT(F14-I14-50,"#,##0_ "),"mm (",C14,"の基礎外周)"," (余掘: 50mm)"),"*")) | P14: =IF(K14>0," ","Dont need to dig")
E15: =IF(C15="","",VLOOKUP(D15,データ!$A$2:$B$12,2,0)) | J15: =IF(C15="","",F15-H15-E15) | K15: =IF(C15="","",IF(A15=1,$E$2-J15,IF(A15=2,$E$3-J15,IF(A15=3,$E$4-J15,IF(A15=4,$E$5-J15,$E$6-J15))))) | L15: =IF(C15="","",IF(D15="TNF-D",50,IF(D15="TNF-DD",50,IF(D15="FW/FG",100,(IF(ABS(K15)>800,100,50)))))) | M15: =IF(C15="","",IF(RIGHT(D15,4)="スロープ",CONCATENATE($D$2," ",TEXT(G15-H15-E15,"#,##0_ "),"mm→",TEXT(J15,"#,##0_ "),"mm (",C15,")"," (余掘: ",L15,"mm)"),IF(D15="TNF-D",CONCATENATE($D$2," ",TEXT(J15,"#,##0_ "),"mm (",C15,"の底面)"),IF(D15="TNF-DD",CONCATENATE($D$2," ",TEXT(J15,"#,##0_ "),"mm (",C15,"の底面)"),CONCATENATE($D$2," ",TEXT(J15,"#,##0_ "),"mm (",C15,")"," (余掘: ",L15,"mm)"))))) | N15: =IF(C15="","",IF(D15="TNF-D",CONCATENATE($D$2," ",TEXT(F15-I15,"#,##0_ "),"mm→",TEXT(J15,"#,##0_ "),"mm (",C15,"の法面)"),IF(D15="TNF-DD",CONCATENATE($D$2," ",TEXT(F15-I15-50,"#,##0_ "),"mm→",TEXT(J15,"#,##0_ "),"mm (",C15,"の法面)"),"*"))) | O15: =IF(C15="","",IF(D15="TNF-DD",CONCATENATE($D$2," ",TEXT(F15-I15-50,"#,##0_ "),"mm (",C15,"の基礎外周)"," (余掘: 50mm)"),"*")) | P15: =IF(K15>0," ","Dont need to dig")
E16: =IF(C16="","",VLOOKUP(D16,データ!$A$2:$B$12,2,0)) | J16: =IF(C16="","",F16-H16-E16) | K16: =IF(C16="","",IF(A16=1,$E$2-J16,IF(A16=2,$E$3-J16,IF(A16=3,$E$4-J16,IF(A16=4,$E$5-J16,$E$6-J16))))) | L16: =IF(C16="","",IF(D16="TNF-D",50,IF(D16="TNF-DD",50,IF(D16="FW/FG",100,(IF(ABS(K16)>800,100,50)))))) | M16: =IF(C16="","",IF(RIGHT(D16,4)="スロープ",CONCATENATE($D$2," ",TEXT(G16-H16-E16,"#,##0_ "),"mm→",TEXT(J16,"#,##0_ "),"mm (",C16,")"," (余掘: ",L16,"mm)"),IF(D16="TNF-D",CONCATENATE($D$2," ",TEXT(J16,"#,##0_ "),"mm (",C16,"の底面)"),IF(D16="TNF-DD",CONCATENATE($D$2," ",TEXT(J16,"#,##0_ "),"mm (",C16,"の底面)"),CONCATENATE($D$2," ",TEXT(J16,"#,##0_ "),"mm (",C16,")"," (余掘: ",L16,"mm)"))))) | N16: =IF(C16="","",IF(D16="TNF-D",CONCATENATE($D$2," ",TEXT(F16-I16,"#,##0_ "),"mm→",TEXT(J16,"#,##0_ "),"mm (",C16,"の法面)"),IF(D16="TNF-DD",CONCATENATE($D$2," ",TEXT(F16-I16-50,"#,##0_ "),"mm→",TEXT(J16,"#,##0_ "),"mm (",C16,"の法面)"),"*"))) | O16: =IF(C16="","",IF(D16="TNF-DD",CONCATENATE($D$2," ",TEXT(F16-I16-50,"#,##0_ "),"mm (",C16,"の基礎外周)"," (余掘: 50mm)"),"*")) | P16: =IF(K16>0," ","Dont need to dig")
E17: =IF(C17="","",VLOOKUP(D17,データ!$A$2:$B$12,2,0)) | J17: =IF(C17="","",F17-H17-E17) | K17: =IF(C17="","",IF(A17=1,$E$2-J17,IF(A17=2,$E$3-J17,IF(A17=3,$E$4-J17,IF(A17=4,$E$5-J17,$E$6-J17))))) | L17: =IF(C17="","",IF(D17="TNF-D",50,IF(D17="TNF-DD",50,IF(D17="FW/FG",100,(IF(ABS(K17)>800,100,50)))))) | M17: =IF(C17="","",IF(RIGHT(D17,4)="スロープ",CONCATENATE($D$2," ",TEXT(G17-H17-E17,"#,##0_ "),"mm→",TEXT(J17,"#,##0_ "),"mm (",C17,")"," (余掘: ",L17,"mm)"),IF(D17="TNF-D",CONCATENATE($D$2," ",TEXT(J17,"#,##0_ "),"mm (",C17,"の底面)"),IF(D17="TNF-DD",CONCATENATE($D$2," ",TEXT(J17,"#,##0_ "),"mm (",C17,"の底面)"),CONCATENATE($D$2," ",TEXT(J17,"#,##0_ "),"mm (",C17,")"," (余掘: ",L17,"mm)"))))) | N17: =IF(C17="","",IF(D17="TNF-D",CONCATENATE($D$2," ",TEXT(F17-I17,"#,##0_ "),"mm→",TEXT(J17,"#,##0_ "),"mm (",C17,"の法面)"),IF(D17="TNF-DD",CONCATENATE($D$2," ",TEXT(F17-I17-50,"#,##0_ "),"mm→",TEXT(J17,"#,##0_ "),"mm (",C17,"の法面)"),"*"))) | O17: =IF(C17="","",IF(D17="TNF-DD",CONCATENATE($D$2," ",TEXT(F17-I17-50,"#,##0_ "),"mm (",C17,"の基礎外周)"," (余掘: 50mm)"),"*")) | P17: =IF(K17>0," ","Dont need to dig")
A18: 1 | E18: =IF(C18="","",VLOOKUP(D18,データ!$A$2:$B$12,2,0)) | J18: =IF(C18="","",F18-H18-E18) | K18: =IF(C18="","",IF(A18=1,$E$2-J18,IF(A18=2,$E$3-J18,IF(A18=3,$E$4-J18,IF(A18=4,$E$5-J18,$E$6-J18))))) | L18: =IF(C18="","",IF(D18="TNF-D",50,IF(D18="TNF-DD",50,IF(D18="FW/FG",100,(IF(ABS(K18)>800,100,50)))))) | M18: =IF(C18="","",IF(RIGHT(D18,4)="スロープ",CONCATENATE($D$2," ",TEXT(G18-H18-E18,"#,##0_ "),"mm→",TEXT(J18,"#,##0_ "),"mm (",C18,")"," (余掘: ",L18,"mm)"),IF(D18="TNF-D",CONCATENATE($D$2," ",TEXT(J18,"#,##0_ "),"mm (",C18,"の底面)"),IF(D18="TNF-DD",CONCATENATE($D$2," ",TEXT(J18,"#,##0_ "),"mm (",C18,"の底面)"),CONCATENATE($D$2," ",TEXT(J18,"#,##0_ "),"mm (",C18,")"," (余掘: ",L18,"mm)"))))) | N18: =IF(C18="","",IF(D18="TNF-D",CONCATENATE($D$2," ",TEXT(F18-I18,"#,##0_ "),"mm→",TEXT(J18,"#,##0_ "),"mm (",C18,"の法面)"),IF(D18="TNF-DD",CONCATENATE($D$2," ",TEXT(F18-I18-50,"#,##0_ "),"mm→",TEXT(J18,"#,##0_ "),"mm (",C18,"の法面)"),"*"))) | O18: =IF(C18="","",IF(D18="TNF-DD",CONCATENATE($D$2," ",TEXT(F18-I18-50,"#,##0_ "),"mm (",C18,"の基礎外周)"," (余掘: 50mm)"),"*")) | P18: =IF(K18>0," ","Dont need to dig")
A19: 1 | E19: =IF(C19="","",VLOOKUP(D19,データ!$A$2:$B$12,2,0)) | J19: =IF(C19="","",F19-H19-E19) | K19: =IF(C19="","",IF(A19=1,$E$2-J19,IF(A19=2,$E$3-J19,IF(A19=3,$E$4-J19,IF(A19=4,$E$5-J19,$E$6-J19))))) | L19: =IF(C19="","",IF(D19="TNF-D",50,IF(D19="TNF-DD",50,IF(D19="FW/FG",100,(IF(ABS(K19)>800,100,50)))))) | M19: =IF(C19="","",IF(RIGHT(D19,4)="スロープ",CONCATENATE($D$2," ",TEXT(G19-H19-E19,"#,##0_ "),"mm→",TEXT(J19,"#,##0_ "),"mm (",C19,")"," (余掘: ",L19,"mm)"),IF(D19="TNF-D",CONCATENATE($D$2," ",TEXT(J19,"#,##0_ "),"mm (",C19,"の底面)"),IF(D19="TNF-DD",CONCATENATE($D$2," ",TEXT(J19,"#,##0_ "),"mm (",C19,"の底面)"),CONCATENATE($D$2," ",TEXT(J19,"#,##0_ "),"mm (",C19,")"," (余掘: ",L19,"mm)"))))) | N19: =IF(C19="","",IF(D19="TNF-D",CONCATENATE($D$2," ",TEXT(F19-I19,"#,##0_ "),"mm→",TEXT(J19,"#,##0_ "),"mm (",C19,"の法面)"),IF(D19="TNF-DD",CONCATENATE($D$2," ",TEXT(F19-I19-50,"#,##0_ "),"mm→",TEXT(J19,"#,##0_ "),"mm (",C19,"の法面)"),"*"))) | O19: =IF(C19="","",IF(D19="TNF-DD",CONCATENATE($D$2," ",TEXT(F19-I19-50,"#,##0_ "),"mm (",C19,"の基礎外周)"," (余掘: 50mm)"),"*")) | P19: =IF(K19>0," ","Dont need to dig")
A20: 1 | E20: =IF(C20="","",VLOOKUP(D20,データ!$A$2:$B$12,2,0)) | J20: =IF(C20="","",F20-H20-E20) | K20: =IF(C20="","",IF(A20=1,$E$2-J20,IF(A20=2,$E$3-J20,IF(A20=3,$E$4-J20,IF(A20=4,$E$5-J20,$E$6-J20))))) | L20: =IF(C20="","",IF(D20="TNF-D",50,IF(D20="TNF-DD",50,IF(D20="FW/FG",100,(IF(ABS(K20)>800,100,50)))))) | M20: =IF(C20="","",IF(RIGHT(D20,4)="スロープ",CONCATENATE($D$2," ",TEXT(G20-H20-E20,"#,##0_ "),"mm→",TEXT(J20,"#,##0_ "),"mm (",C20,")"," (余掘: ",L20,"mm)"),IF(D20="TNF-D",CONCATENATE($D$2," ",TEXT(J20,"#,##0_ "),"mm (",C20,"の底面)"),IF(D20="TNF-DD",CONCATENATE($D$2," ",TEXT(J20,"#,##0_ "),"mm (",C20,"の底面)"),CONCATENATE($D$2," ",TEXT(J20,"#,##0_ "),"mm (",C20,")"," (余掘: ",L20,"mm)"))))) | N20: =IF(C20="","",IF(D20="TNF-D",CONCATENATE($D$2," ",TEXT(F20-I20,"#,##0_ "),"mm→",TEXT(J20,"#,##0_ "),"mm (",C20,"の法面)"),IF(D20="TNF-DD",CONCATENATE($D$2," ",TEXT(F20-I20-50,"#,##0_ "),"mm→",TEXT(J20,"#,##0_ "),"mm (",C20,"の法面)"),"*"))) | O20: =IF(C20="","",IF(D20="TNF-DD",CONCATENATE($D$2," ",TEXT(F20-I20-50,"#,##0_ "),"mm (",C20,"の基礎外周)"," (余掘: 50mm)"),"*")) | P20: =IF(K20>0," ","Dont need to dig")
A21: 1 | E21: =IF(C21="","",VLOOKUP(D21,データ!$A$2:$B$12,2,0)) | J21: =IF(C21="","",F21-H21-E21) | K21: =IF(C21="","",IF(A21=1,$E$2-J21,IF(A21=2,$E$3-J21,IF(A21=3,$E$4-J21,IF(A21=4,$E$5-J21,$E$6-J21))))) | L21: =IF(C21="","",IF(D21="TNF-D",50,IF(D21="TNF-DD",50,IF(D21="FW/FG",100,(IF(ABS(K21)>800,100,50)))))) | M21: =IF(C21="","",IF(RIGHT(D21,4)="スロープ",CONCATENATE($D$2," ",TEXT(G21-H21-E21,"#,##0_ "),"mm→",TEXT(J21,"#,##0_ "),"mm (",C21,")"," (余掘: ",L21,"mm)"),IF(D21="TNF-D",CONCATENATE($D$2," ",TEXT(J21,"#,##0_ "),"mm (",C21,"の底面)"),IF(D21="TNF-DD",CONCATENATE($D$2," ",TEXT(J21,"#,##0_ "),"mm (",C21,"の底面)"),CONCATENATE($D$2," ",TEXT(J21,"#,##0_ "),"mm (",C21,")"," (余掘: ",L21,"mm)"))))) | N21: =IF(C21="","",IF(D21="TNF-D",CONCATENATE($D$2," ",TEXT(F21-I21,"#,##0_ "),"mm→",TEXT(J21,"#,##0_ "),"mm (",C21,"の法面)"),IF(D21="TNF-DD",CONCATENATE($D$2," ",TEXT(F21-I21-50,"#,##0_ "),"mm→",TEXT(J21,"#,##0_ "),"mm (",C21,"の法面)"),"*"))) | O21: =IF(C21="","",IF(D21="TNF-DD",CONCATENATE($D$2," ",TEXT(F21-I21-50,"#,##0_ "),"mm (",C21,"の基礎外周)"," (余掘: 50mm)"),"*")) | P21: =IF(K21>0," ","Dont need to dig")
A22: 1 | E22: =IF(C22="","",VLOOKUP(D22,データ!$A$2:$B$12,2,0)) | J22: =IF(C22="","",F22-H22-E22) | K22: =IF(C22="","",IF(A22=1,$E$2-J22,IF(A22=2,$E$3-J22,IF(A22=3,$E$4-J22,IF(A22=4,$E$5-J22,$E$6-J22))))) | L22: =IF(C22="","",IF(D22="TNF-D",50,IF(D22="TNF-DD",50,IF(D22="FW/FG",100,(IF(ABS(K22)>800,100,50)))))) | M22: =IF(C22="","",IF(RIGHT(D22,4)="スロープ",CONCATENATE($D$2," ",TEXT(G22-H22-E22,"#,##0_ "),"mm→",TEXT(J22,"#,##0_ "),"mm (",C22,")"," (余掘: ",L22,"mm)"),IF(D22="TNF-D",CONCATENATE($D$2," ",TEXT(J22,"#,##0_ "),"mm (",C22,"の底面)"),IF(D22="TNF-DD",CONCATENATE($D$2," ",TEXT(J22,"#,##0_ "),"mm (",C22,"の底面)"),CONCATENATE($D$2," ",TEXT(J22,"#,##0_ "),"mm (",C22,")"," (余掘: ",L22,"mm)"))))) | N22: =IF(C22="","",IF(D22="TNF-D",CONCATENATE($D$2," ",TEXT(F22-I22,"#,##0_ "),"mm→",TEXT(J22,"#,##0_ "),"mm (",C22,"の法面)"),IF(D22="TNF-DD",CONCATENATE($D$2," ",TEXT(F22-I22-50,"#,##0_ "),"mm→",TEXT(J22,"#,##0_ "),"mm (",C22,"の法面)"),"*"))) | O22: =IF(C22="","",IF(D22="TNF-DD",CONCATENATE($D$2," ",TEXT(F22-I22-50,"#,##0_ "),"mm (",C22,"の基礎外周)"," (余掘: 50mm)"),"*")) | P22: =IF(K22>0," ","Dont need to dig")
A23: 1 | E23: =IF(C23="","",VLOOKUP(D23,データ!$A$2:$B$12,2,0)) | J23: =IF(C23="","",F23-H23-E23) | K23: =IF(C23="","",IF(A23=1,$E$2-J23,IF(A23=2,$E$3-J23,IF(A23=3,$E$4-J23,IF(A23=4,$E$5-J23,$E$6-J23))))) | L23: =IF(C23="","",IF(D23="TNF-D",50,IF(D23="TNF-DD",50,IF(D23="FW/FG",100,(IF(ABS(K23)>800,100,50)))))) | M23: =IF(C23="","",IF(RIGHT(D23,4)="スロープ",CONCATENATE($D$2," ",TEXT(G23-H23-E23,"#,##0_ "),"mm→",TEXT(J23,"#,##0_ "),"mm (",C23,")"," (余掘: ",L23,"mm)"),IF(D23="TNF-D",CONCATENATE($D$2," ",TEXT(J23,"#,##0_ "),"mm (",C23,"の底面)"),IF(D23="TNF-DD",CONCATENATE($D$2," ",TEXT(J23,"#,##0_ "),"mm (",C23,"の底面)"),CONCATENATE($D$2," ",TEXT(J23,"#,##0_ "),"mm (",C23,")"," (余掘: ",L23,"mm)"))))) | N23: =IF(C23="","",IF(D23="TNF-D",CONCATENATE($D$2," ",TEXT(F23-I23,"#,##0_ "),"mm→",TEXT(J23,"#,##0_ "),"mm (",C23,"の法面)"),IF(D23="TNF-DD",CONCATENATE($D$2," ",TEXT(F23-I23-50,"#,##0_ "),"mm→",TEXT(J23,"#,##0_ "),"mm (",C23,"の法面)"),"*"))) | O23: =IF(C23="","",IF(D23="TNF-DD",CONCATENATE($D$2," ",TEXT(F23-I23-50,"#,##0_ "),"mm (",C23,"の基礎外周)"," (余掘: 50mm)"),"*")) | P23: =IF(K23>0," ","Dont need to dig")
A24: 1 | E24: =IF(C24="","",VLOOKUP(D24,データ!$A$2:$B$12,2,0)) | J24: =IF(C24="","",F24-H24-E24) | K24: =IF(C24="","",IF(A24=1,$E$2-J24,IF(A24=2,$E$3-J24,IF(A24=3,$E$4-J24,IF(A24=4,$E$5-J24,$E$6-J24))))) | L24: =IF(C24="","",IF(D24="TNF-D",50,IF(D24="TNF-DD",50,IF(D24="FW/FG",100,(IF(ABS(K24)>800,100,50)))))) | M24: =IF(C24="","",IF(RIGHT(D24,4)="スロープ",CONCATENATE($D$2," ",TEXT(G24-H24-E24,"#,##0_ "),"mm→",TEXT(J24,"#,##0_ "),"mm (",C24,")"," (余掘: ",L24,"mm)"),IF(D24="TNF-D",CONCATENATE($D$2," ",TEXT(J24,"#,##0_ "),"mm (",C24,"の底面)"),IF(D24="TNF-DD",CONCATENATE($D$2," ",TEXT(J24,"#,##0_ "),"mm (",C24,"の底面)"),CONCATENATE($D$2," ",TEXT(J24,"#,##0_ "),"mm (",C24,")"," (余掘: ",L24,"mm)"))))) | N24: =IF(C24="","",IF(D24="TNF-D",CONCATENATE($D$2," ",TEXT(F24-I24,"#,##0_ "),"mm→",TEXT(J24,"#,##0_ "),"mm (",C24,"の法面)"),IF(D24="TNF-DD",CONCATENATE($D$2," ",TEXT(F24-I24-50,"#,##0_ "),"mm→",TEXT(J24,"#,##0_ "),"mm (",C24,"の法面)"),"*"))) | O24: =IF(C24="","",IF(D24="TNF-DD",CONCATENATE($D$2," ",TEXT(F24-I24-50,"#,##0_ "),"mm (",C24,"の基礎外周)"," (余掘: 50mm)"),"*")) | P24: =IF(K24>0," ","Dont need to dig")
A25: 1 | E25: =IF(C25="","",VLOOKUP(D25,データ!$A$2:$B$12,2,0)) | J25: =IF(C25="","",F25-H25-E25) | K25: =IF(C25="","",IF(A25=1,$E$2-J25,IF(A25=2,$E$3-J25,IF(A25=3,$E$4-J25,IF(A25=4,$E$5-J25,$E$6-J25))))) | L25: =IF(C25="","",IF(D25="TNF-D",50,IF(D25="TNF-DD",50,IF(D25="FW/FG",100,(IF(ABS(K25)>800,100,50)))))) | M25: =IF(C25="","",IF(RIGHT(D25,4)="スロープ",CONCATENATE($D$2," ",TEXT(G25-H25-E25,"#,##0_ "),"mm→",TEXT(J25,"#,##0_ "),"mm (",C25,")"," (余掘: ",L25,"mm)"),IF(D25="TNF-D",CONCATENATE($D$2," ",TEXT(J25,"#,##0_ "),"mm (",C25,"の底面)"),IF(D25="TNF-DD",CONCATENATE($D$2," ",TEXT(J25,"#,##0_ "),"mm (",C25,"の底面)"),CONCATENATE($D$2," ",TEXT(J25,"#,##0_ "),"mm (",C25,")"," (余掘: ",L25,"mm)"))))) | N25: =IF(C25="","",IF(D25="TNF-D",CONCATENATE($D$2," ",TEXT(F25-I25,"#,##0_ "),"mm→",TEXT(J25,"#,##0_ "),"mm (",C25,"の法面)"),IF(D25="TNF-DD",CONCATENATE($D$2," ",TEXT(F25-I25-50,"#,##0_ "),"mm→",TEXT(J25,"#,##0_ "),"mm (",C25,"の法面)"),"*"))) | O25: =IF(C25="","",IF(D25="TNF-DD",CONCATENATE($D$2," ",TEXT(F25-I25-50,"#,##0_ "),"mm (",C25,"の基礎外周)"," (余掘: 50mm)"),"*")) | P25: =IF(K25>0," ","Dont need to dig")
A26: 1 | E26: =IF(C26="","",VLOOKUP(D26,データ!$A$2:$B$12,2,0)) | J26: =IF(C26="","",F26-H26-E26) | K26: =IF(C26="","",IF(A26=1,$E$2-J26,IF(A26=2,$E$3-J26,IF(A26=3,$E$4-J26,IF(A26=4,$E$5-J26,$E$6-J26))))) | L26: =IF(C26="","",IF(D26="TNF-D",50,IF(D26="TNF-DD",50,IF(D26="FW/FG",100,(IF(ABS(K26)>800,100,50)))))) | M26: =IF(C26="","",IF(RIGHT(D26,4)="スロープ",CONCATENATE($D$2," ",TEXT(G26-H26-E26,"#,##0_ "),"mm→",TEXT(J26,"#,##0_ "),"mm (",C26,")"," (余掘: ",L26,"mm)"),IF(D26="TNF-D",CONCATENATE($D$2," ",TEXT(J26,"#,##0_ "),"mm (",C26,"の底面)"),IF(D26="TNF-DD",CONCATENATE($D$2," ",TEXT(J26,"#,##0_ "),"mm (",C26,"の底面)"),CONCATENATE($D$2," ",TEXT(J26,"#,##0_ "),"mm (",C26,")"," (余掘: ",L26,"mm)"))))) | N26: =IF(C26="","",IF(D26="TNF-D",CONCATENATE($D$2," ",TEXT(F26-I26,"#,##0_ "),"mm→",TEXT(J26,"#,##0_ "),"mm (",C26,"の法面)"),IF(D26="TNF-DD",CONCATENATE($D$2," ",TEXT(F26-I26-50,"#,##0_ "),"mm→",TEXT(J26,"#,##0_ "),"mm (",C26,"の法面)"),"*"))) | O26: =IF(C26="","",IF(D26="TNF-DD",CONCATENATE($D$2," ",TEXT(F26-I26-50,"#,##0_ "),"mm (",C26,"の基礎外周)"," (余掘: 50mm)"),"*")) | P26: =IF(K26>0," ","Dont need to dig")
A27: 1 | E27: =IF(C27="","",VLOOKUP(D27,データ!$A$2:$B$12,2,0)) | J27: =IF(C27="","",F27-H27-E27) | K27: =IF(C27="","",IF(A27=1,$E$2-J27,IF(A27=2,$E$3-J27,IF(A27=3,$E$4-J27,IF(A27=4,$E$5-J27,$E$6-J27))))) | L27: =IF(C27="","",IF(D27="TNF-D",50,IF(D27="TNF-DD",50,IF(D27="FW/FG",100,(IF(ABS(K27)>800,100,50)))))) | M27: =IF(C27="","",IF(RIGHT(D27,4)="スロープ",CONCATENATE($D$2," ",TEXT(G27-H27-E27,"#,##0_ "),"mm→",TEXT(J27,"#,##0_ "),"mm (",C27,")"," (余掘: ",L27,"mm)"),IF(D27="TNF-D",CONCATENATE($D$2," ",TEXT(J27,"#,##0_ "),"mm (",C27,"の底面)"),IF(D27="TNF-DD",CONCATENATE($D$2," ",TEXT(J27,"#,##0_ "),"mm (",C27,"の底面)"),CONCATENATE($D$2," ",TEXT(J27,"#,##0_ "),"mm (",C27,")"," (余掘: ",L27,"mm)"))))) | N27: =IF(C27="","",IF(D27="TNF-D",CONCATENATE($D$2," ",TEXT(F27-I27,"#,##0_ "),"mm→",TEXT(J27,"#,##0_ "),"mm (",C27,"の法面)"),IF(D27="TNF-DD",CONCATENATE($D$2," ",TEXT(F27-I27-50,"#,##0_ "),"mm→",TEXT(J27,"#,##0_ "),"mm (",C27,"の法面)"),"*"))) | O27: =IF(C27="","",IF(D27="TNF-DD",CONCATENATE($D$2," ",TEXT(F27-I27-50,"#,##0_ "),"mm (",C27,"の基礎外周)"," (余掘: 50mm)"),"*")) | P27: =IF(K27>0," ","Dont need to dig")
A28: 1 | E28: =IF(C28="","",VLOOKUP(D28,データ!$A$2:$B$12,2,0)) | J28: =IF(C28="","",F28-H28-E28) | K28: =IF(C28="","",IF(A28=1,$E$2-J28,IF(A28=2,$E$3-J28,IF(A28=3,$E$4-J28,IF(A28=4,$E$5-J28,$E$6-J28))))) | L28: =IF(C28="","",IF(D28="TNF-D",50,IF(D28="TNF-DD",50,IF(D28="FW/FG",100,(IF(ABS(K28)>800,100,50)))))) | M28: =IF(C28="","",IF(RIGHT(D28,4)="スロープ",CONCATENATE($D$2," ",TEXT(G28-H28-E28,"#,##0_ "),"mm→",TEXT(J28,"#,##0_ "),"mm (",C28,")"," (余掘: ",L28,"mm)"),IF(D28="TNF-D",CONCATENATE($D$2," ",TEXT(J28,"#,##0_ "),"mm (",C28,"の底面)"),IF(D28="TNF-DD",CONCATENATE($D$2," ",TEXT(J28,"#,##0_ "),"mm (",C28,"の底面)"),CONCATENATE($D$2," ",TEXT(J28,"#,##0_ "),"mm (",C28,")"," (余掘: ",L28,"mm)"))))) | N28: =IF(C28="","",IF(D28="TNF-D",CONCATENATE($D$2," ",TEXT(F28-I28,"#,##0_ "),"mm→",TEXT(J28,"#,##0_ "),"mm (",C28,"の法面)"),IF(D28="TNF-DD",CONCATENATE($D$2," ",TEXT(F28-I28-50,"#,##0_ "),"mm→",TEXT(J28,"#,##0_ "),"mm (",C28,"の法面)"),"*"))) | O28: =IF(C28="","",IF(D28="TNF-DD",CONCATENATE($D$2," ",TEXT(F28-I28-50,"#,##0_ "),"mm (",C28,"の基礎外周)"," (余掘: 50mm)"),"*")) | P28: =IF(K28>0," ","Dont need to dig")
A29: 1 | E29: =IF(C29="","",VLOOKUP(D29,データ!$A$2:$B$12,2,0)) | J29: =IF(C29="","",F29-H29-E29) | K29: =IF(C29="","",IF(A29=1,$E$2-J29,IF(A29=2,$E$3-J29,IF(A29=3,$E$4-J29,IF(A29=4,$E$5-J29,$E$6-J29))))) | L29: =IF(C29="","",IF(D29="TNF-D",50,IF(D29="TNF-DD",50,IF(D29="FW/FG",100,(IF(ABS(K29)>800,100,50)))))) | M29: =IF(C29="","",IF(RIGHT(D29,4)="スロープ",CONCATENATE($D$2," ",TEXT(G29-H29-E29,"#,##0_ "),"mm→",TEXT(J29,"#,##0_ "),"mm (",C29,")"," (余掘: ",L29,"mm)"),IF(D29="TNF-D",CONCATENATE($D$2," ",TEXT(J29,"#,##0_ "),"mm (",C29,"の底面)"),IF(D29="TNF-DD",CONCATENATE($D$2," ",TEXT(J29,"#,##0_ "),"mm (",C29,"の底面)"),CONCATENATE($D$2," ",TEXT(J29,"#,##0_ "),"mm (",C29,")"," (余掘: ",L29,"mm)"))))) | N29: =IF(C29="","",IF(D29="TNF-D",CONCATENATE($D$2," ",TEXT(F29-I29,"#,##0_ "),"mm→",TEXT(J29,"#,##0_ "),"mm (",C29,"の法面)"),IF(D29="TNF-DD",CONCATENATE($D$2," ",TEXT(F29-I29-50,"#,##0_ "),"mm→",TEXT(J29,"#,##0_ "),"mm (",C29,"の法面)"),"*"))) | O29: =IF(C29="","",IF(D29="TNF-DD",CONCATENATE($D$2," ",TEXT(F29-I29-50,"#,##0_ "),"mm (",C29,"の基礎外周)"," (余掘: 50mm)"),"*")) | P29: =IF(K29>0," ","Dont need to dig")
... A48: 1 | E48: =IF(C48="","",VLOOKUP(D48,データ!$A$2:$B$12,2,0)) | J48: =IF(C48="","",F48-H48-E48) | K48: =IF(C48="","",IF(A48=1,$E$2-J48,IF(A48=2,$E$3-J48,IF(A48=3,$E$4-J48,IF(A48=4,$E$5-J48,$E$6-J48))))) | L48: =IF(C48="","",IF(D48="TNF-D",50,IF(D48="TNF-DD",50,IF(D48="FW/FG",100,(IF(ABS(K48)>800,100,50)))))) | M48: =IF(C48="","",IF(RIGHT(D48,4)="スロープ",CONCATENATE($D$2," ",TEXT(G48-H48-E48,"#,##0_ "),"mm→",TEXT(J48,"#,##0_ "),"mm (",C48,")"," (余掘: ",L48,"mm)"),IF(D48="TNF-D",CONCATENATE($D$2," ",TEXT(J48,"#,##0_ "),"mm (",C48,"の底面)"),IF(D48="TNF-DD",CONCATENATE($D$2," ",TEXT(J48,"#,##0_ "),"mm (",C48,"の底面)"),CONCATENATE($D$2," ",TEXT(J48,"#,##0_ "),"mm (",C48,")"," (余掘: ",L48,"mm)"))))) | N48: =IF(C48="","",IF(D48="TNF-D",CONCATENATE($D$2," ",TEXT(F48-I48,"#,##0_ "),"mm→",TEXT(J48,"#,##0_ "),"mm (",C48,"の法面)"),IF(D48="TNF-DD",CONCATENATE($D$2," ",TEXT(F48-I48-50,"#,##0_ "),"mm→",TEXT(J48,"#,##0_ "),"mm (",C48,"の法面)"),"*"))) | O48: =IF(C48="","",IF(D48="TNF-DD",CONCATENATE($D$2," ",TEXT(F48-I48-50,"#,##0_ "),"mm (",C48,"の基礎外周)"," (余掘: 50mm)"),"*")) | P48: =IF(K48>0," ","Dont need to dig")

Sheet Check Long Rebar
A1: CHECK LONG REBAR
B2: X1 | C2: X2 | D2: Y | E2: X2 | F2: X1 | H2: L long
A4: Type 1 | E4: =C4 -> 0 | F4: =B4 -> 0 | H4: =IF(D4="","",SUM(B4:F4))
A6: Type 2 | E6: =C6 -> 0 | F6: =B6 -> 0 | H6: =IF(D6="","",SUM(B6:F6))
A8: Type 3 | E8: =C8 -> 0 | F8: =B8 -> 0 | H8: =IF(D8="","",SUM(B8:F8))
A10: Type 4 | E10: =C10 -> 0 | F10: =B10 -> 0 | H10: =IF(D10="","",SUM(B10:F10))
A12: Type 5 | E12: =C12 -> 0 | F12: =B12 -> 0 | H12: =IF(D12="","",SUM(B12:F12))
A14: Type 6 | E14: =C14 -> 0 | F14: =B14 -> 0 | H14: =IF(D14="","",SUM(B14:F14))
A16: Type 7 | E16: =C16 -> 0 | F16: =B16 -> 0 | H16: =IF(D16="","",SUM(B16:F16))
A18: Type 8 | E18: =C18 -> 0 | F18: =B18 -> 0 | H18: =IF(D18="","",SUM(B18:F18))
A20: Type 9 | E20: =C20 -> 0 | F20: =B20 -> 0 | H20: =IF(D20="","",SUM(B20:F20))
A22: Type 10 | E22: =C22 -> 0 | F22: =B22 -> 0 | H22: =IF(D22="","",SUM(B22:F22))
A24: Type 11 | E24: =C24 -> 0 | F24: =B24 -> 0 | H24: =IF(D24="","",SUM(B24:F24))
A26: Type 12 | E26: =C26 -> 0 | F26: =B26 -> 0 | H26: =IF(D26="","",SUM(B26:F26))
... A34: Type 16 | E34: =C34 -> 0 | F34: =B34 -> 0 | H34: =IF(D34="","",SUM(B34:F34))

Sheet データ
A2: TNF-D | B2: 100
A3: TNF-DD | B3: 100
A4: TNF | B4: 50
A5: FW/FG | B5: 50
A6: FW-間柱 | B6: 100
A7: ピット | B7: 50
A8: 土間 | B8: 0
A9: 土間スロープ | B9: 0
A10: FW/FGスロープ | B10: 50
A11: 他の50mm | B11: 50
A12: 他の100mm | B12: 100
A18: 設計GL
A19: GL
A20: SGL
A21: FL
